## 예외 처리

***

<br>

### :pushpin: 예외상황 처리 기능

예외상황의 인식과 발생, 예외상황의 처리 요소로 이루어진다.

<br>

### :pushpin: 예외발생 시

1. 프로그램의 실행이 일시 정지
2. 예외상황 처리 기능 -> 발생된 예외상황을 처리할 수 있는 프로그램 부분을 찾는다.
3. 예외상황 처리 이후 -> 예외상황을 처리한 프로그램 부분에서 정지된 실행이 속개된다.

이전에 ```LibMat```, ```Book```, ```AudioBook``` 클래스를 이용한 예외 처리 클래스 만들기

```c++
#ifndef LIBMAT_EXCEPTION_H
#define LIBMAT_EXCEPTION_H

class LibMat_exception{
    public:
    LibMat_exception(std::string &title, std::string &author) : _title(title), _author(author){
        std::cerr<<"exception constructor\n";
    }

    void what_happened(){
        std::cerr<<"LibMat_exception\n";
    }

    private:
    std::string _title;
    std::string _author;
};

#endif
```

예외 발생 시에 throw 표현식을 통해 LibMat의 오류를 처리하는 ```LibMat_exception``` 클래스의 생성자를 호출

예외상황이 발생한 후에 throw를 통해 예외처리 클래스의 생성자가 호출된 것을 볼 수 있다.

위 오류는 Book 클래스의 생성자로 Hello와 C++ 인자를 전달받았을 때 호출되도록 하였다.

```c++
int main(){ throw Book("Hello", "C++"); }
```

<br>

### :pushpin: 예외상황 메커니즘

1. throw 표현식이 있는 곳을 보고 try 블록 안에 있는지 찾는다.

   - try 블록에 있다면?

     그 예외상황을 처리할 수 있는 catch절이 있는지 조사 .. [1]

     catch절도 있다면 예외상황 처리, 프로그램 속개 .. [2]

   - try 블록에는 있지만, catch절이 없다면?

     try 블록이 없는 것으로 처리된다.

     

<br>

### :pushpin: 지역 리소스 관리

```c++
void f(){
	int *p = new int;
  m.acquire();
  process(p);
  m.release();
  delete p;
}
```

위 코드의 문제는 함수의 시작에서 얻는 리소스를 반드시 해제하리라고 보장할 수 없다는 것

```process()``` 또는 ```process()``` 내부에서 호출된 함수가 예외상황을 발생시킨다면 process() 다음에 오는 구문은 실행되지 않는다.



**[해결책]**

```c++
void f(){
  try{
    int *p = new int;
    m.acquire();
    process(p); 
  }
  catch(...){
    m.release();
    delete p;
  }
}
```

```process()```에서 문제 발생 시 catch 블록에 탐지되어 try블록에서 얻었던 리소스를 해제하는 구문을 실행한다.

<br>

### :pushpin: 표준 예외상황

new 연산자는 프로그램의 빈 공간으로부터 메모리를 획득할 수 있지만, 그렇지 않다면 ```bad_alloc``` 예외상황 객체를 발생시킨다.

```c++
vector<string> * init_text_vector(ifstream &infile){
  vector<string> *ptext=0;
  
  try{
    ptext = new vector<string>;
  }
  catch(bac_alloc){
    cerr<<"heap memory exhausted\n";
  }
  return ptext;
}
```

```ptext=new vector<string>;``` 대입문은 heap 객체에서 필요한 메모리를 할당하고, 할당된 메모리 주소를 ptext에 대입한다.

```vector<string>``` 객체를 나타내는 메모리가 사용 불가능하다면 기본 생성자는 호출되지 않고, ptext에도 대입되지 않는다. 

bad_alloc 예외상황 객체가 발생하고, try 블록 뒤에 나오는 관련 catch절로 이동된다.

이러한 bad_alloc과 같은 표준 라이브러리에 정의된 exception 클래스 계층이 존재한다.

bad_alloc 클래스는 exception 기본 클래스로부터 파생되었으며, exception 기본 클래스로부터 또다른 사용자 정의 예외처리 클래스를 파생시킬 수 있다.

아래는 해당 예시이며 기본적으로 제공하는 what() 인스턴스를 제공해야 한다.

```c++
#include <exception>

class iterator_overflow : public exception{
  iterator_overflow() : _index(index), _max(max){ }
  
  int index() { return _index; }
  int max() { return _max; }
  const char* what() const;
  
  private:
  int _index;
  int _max;
};
```

iterator_overflow가 exception 클래스 계층을 상속받은 장점은 추상 기본 클래스인 exception을 탐지하는 모든 코드에 의해 iterator_overflow역시 탐지될 수 있다.

```c++
catch(const exception &ex){
  cerr<<ex.what()<<endl;
}
```

이는 exception으로부터 파생된 어떤 클래스도 일치된다.



아래는 iterator_overflow의 what() 인스턴스의 구현이다.

```c++
#include <exception>
#include <sstream>
#include <string>

class iterator_overflow : public exception{
  iterator_overflow() : _index(index), _max(max){ }
  
  int index() { return _index; }
  int max() { return _max; }
  const char* what() const;
  
  private:
  int _index;
  int _max;
};

const char* iterator_overflow::what() const{
  ostringstream ex_msg;
  static string msg;
  
  ex_msg<<"internal error : "<<_index<<" exceeds maximum bound : "<<_max;
  msg = ex_msg.str();
  return msg.c_str(); // char* 표현으로 추출
}
```

```ostringstream``` 클래스는 string 객체에 대해 메모리로의 출력 연산을 지원(sstream 헤더 필요)

:point_right: 다양한 데이터 타입을 하나의 문자열로 표현할 때 유용